Workbook

Sheet Inflation Rates 
A1: Date | B1: CPI (Annual % change)
A2: 6118 | B2: 7.9
A3: 6483 | B3: 9.8
A4: 6848 | B4: 12.3
A5: 7213 | B5: 9.2
A6: 7396 | B6: 11.9
A7: 7579 | B7: 15.4
A8: 7761 | B8: 8.7
A9: 7944 | B9: -1.8
A10: 8126 | B10: -11.1
A11: 8309 | B11: -10.8
A12: 8491 | B12: -4.8
A13: 8674 | B13: -0.4
... A395: 44104 | B395: 1.4
A396: 44196 | B396: 1.4 | G396: Years not considered | H396: Inflation Percentage
A397: 44286 | B397: 1.5
A398: 45382 | B398: 4 | G398: 44377 | H398: 3.3
A399: 45473 | B399: 3.3 | G399: 44469 | H399: 4.9
A400: 45565 | B400: 2.2 | G400: 44561 | H400: 5.9
A401: Mean | B401: =AVERAGE(B356:B400) -> 1.6866667 | G401: 44651 | H401: 6.9
A402: Standard Deviation | B402: =_xlfn.STDEV.S(B356:B400) -> 1.1925145 | G402: 44742 | H402: 7.3
G403: 44834 | H403: 7.2
G404: 44926 | H404: 7.2
G405: 45016 | H405: 6.7
G406: 45107 | H406: 6
G407: 45199 | H407: 5.6
G408: 45291 | H408: 4.7

Sheet Expense Tracker
A1: Weekly expenses | B1: 1110.1
A2: Yearly Expenses | B2: =12*4*B1 -> 53284.8
A3: Current Inflation | B3: 2.2
A5: Age | B5: Infation rates | C5: Expenses
A6: 30 | B6: =AVERAGE(B62:ALM62) -> 1.7061091 | C6: =B2*(1+B6/100) -> 54193.897
A7: 31 | B7: =AVERAGE(B63:ALM63) -> 1.7006627 | C7: =C6*(1+B7/100) -> 55115.552
A8: 32 | B8: =AVERAGE(B64:ALM64) -> 1.6763279 | C8: =C7*(1+B8/100) -> 56039.47
A9: 33 | B9: =AVERAGE(B65:ALM65) -> 1.6708117 | C9: =C8*(1+B9/100) -> 56975.784
A10: 34 | B10: =AVERAGE(B66:ALM66) -> 1.7009746 | C10: =C9*(1+B10/100) -> 57944.927
A11: 35 | B11: =AVERAGE(B67:ALM67) -> 1.6118771 | C11: =C10*(1+B11/100) -> 58878.928
A12: 36 | B12: =AVERAGE(B68:ALM68) -> 1.7116168 | C12: =C11*(1+B12/100) -> 59886.71
A13: 37 | B13: =AVERAGE(B69:ALM69) -> 1.6813549 | C13: =C12*(1+B13/100) -> 60893.618
A14: 38 | B14: =AVERAGE(B70:ALM70) -> 1.7174928 | C14: =C13*(1+B14/100) -> 61939.461
A15: 39 | B15: =AVERAGE(B71:ALM71) -> 1.7690198 | C15: =C14*(1+B15/100) -> 63035.183
A16: 40 | B16: =AVERAGE(B72:ALM72) -> 1.720499 | C16: =C15*(1+B16/100) -> 64119.702
A17: 41 | B17: =AVERAGE(B73:ALM73) -> 1.6589629 | C17: =C16*(1+B17/100) -> 65183.425
A18: 42 | B18: =AVERAGE(B74:ALM74) -> 1.6527065 | C18: =C17*(1+B18/100) -> 66260.715
... A58: 82 | B58: =AVERAGE(B114:ALM114) -> 1.7342651 | C58: =C57*(1+B58/100) -> 129360.78
A61: Age | B61: 1 | C61: 2 | D61: 3 | E61: 4 | F61: 5 | G61: 6 | H61: 7 | I61: 8 | J61: 9 | K61: 10 | L61: 11 | M61: 12 | N61: 13 | O61: 14 | P61: 15 | Q61: 16 | R61: 17 | S61: 18 | T61: 19 | U61: 20 | V61: 21 | W61: 22 | X61: 23 | Y61: 24 | Z61: 25 | AA61: 26 | AB61: 27 | AC61: 28 | AD61: 29 | AE61: 30 | AF61: 31 | AG61: 32 | AH61: 33 | AI61: 34 | AJ61: 35 | AK61: 36 | AL61: 37 | AM61: 38 | AN61: 39 | AO61: 40 | AP61: 41 | AQ61: 42 | AR61: 43 | AS61: 44 | AT61: 45 | AU61: 46 | AV61: 47 | AW61: 48 | AX61: 49 | AY61: 50 | AZ61: 51 | BA61: 52 | BB61: 53 | BC61: 54 | BD61: 55 | BE61: 56 | BF61: 57 | BG61: 58 | BH61: 59 | BI61: 60 | BJ61: 61 | BK61: 62 | BL61: 63 | BM61: 64 | BN61: 65 | BO61: 66 | BP61: 67 | BQ61: 68 | BR61: 69 | BS61: 70 | BT61: 71 | BU61: 72 | BV61: 73 | BW61: 74 | BX61: 75 | BY61: 76 | BZ61: 77 | CA61: 78 | CB61: 79 | CC61: 80 | CD61: 81 | CE61: 82 | CF61: 83 | CG61: 84 | CH61: 85 | CI61: 86 | CJ61: 87 | CK61: 88 | CL61: 89 | CM61: 90 | CN61: 91 | CO61: 92 | CP61: 93 | CQ61: 94 | CR61: 95 | CS61: 96 | CT61: 97 | CU61: 98 | CV61: 99 | CW61: 100 | CX61: 101 | CY61: 102 | CZ61: 103 | DA61: 104 | DB61: 105 | DC61: 106 | DD61: 107 | DE61: 108 | DF61: 109 | DG61: 110 | DH61: 111 | DI61: 112 | DJ61: 113 | DK61: 114 | DL61: 115 | DM61: 116 | DN61: 117 | DO61: 118 | DP61: 119 | DQ61: 120 | DR61: 121 | DS61: 122 | DT61: 123 | DU61: 124 | DV61: 125 | DW61: 126 | DX61: 127 | DY61: 128 | DZ61: 129 | EA61: 130 | EB61: 131 | EC61: 132 | ED61: 133 | EE61: 134 | EF61: 135 | EG61: 136 | EH61: 137 | EI61: 138 | EJ61: 139 | EK61: 140 | EL61: 141 | EM61: 142 | EN61: 143 | EO61: 144 | EP61: 145 | EQ61: 146 | ER61: 147 | ES61: 148 | ET61: 149 | EU61: 150 | EV61: 151 | EW61: 152 | EX61: 153 | EY61: 154 | EZ61: 155 | FA61: 156 | FB61: 157 | FC61: 158 | FD61: 159 | FE61: 160 | FF61: 161 | FG61: 162 | FH61: 163 | FI61: 164 | FJ61: 165 | FK61: 166 | FL61: 167 | FM61: 168 | FN61: 169 | FO61: 170 | FP61: 171 | FQ61: 172 | FR61: 173 | FS61: 174 | FT61: 175 | FU61: 176 | FV61: 177 | FW61: 178 | FX61: 179 | FY61: 180 | FZ61: 181 | GA61: 182 | GB61: 183 | GC61: 184 | GD61: 185 | GE61: 186 | GF61: 187 | GG61: 188 | GH61: 189 | GI61: 190 | GJ61: 191 | GK61: 192 | GL61: 193 | GM61: 194 | GN61: 195 | GO61: 196 | GP61: 197 | GQ61: 198 | GR61: 199 | GS61: 200 | GT61: 201 | GU61: 202 | GV61: 203 | GW61: 204 | GX61: 205 | GY61: 206 | GZ61: 207 | HA61: 208 | HB61: 209 | HC61: 210 | HD61: 211 | HE61: 212 | HF61: 213 | HG61: 214 | HH61: 215 | HI61: 216 | HJ61: 217 | HK61: 218 | HL61: 219 | HM61: 220 | HN61: 221 | HO61: 222 | HP61: 223 | HQ61: 224 | HR61: 225 | HS61: 226 | HT61: 227 | HU61: 228 | HV61: 229 | HW61: 230 | HX61: 231 | HY61: 232 | HZ61: 233 | IA61: 234 | IB61: 235 | IC61: 236 | ID61: 237 | IE61: 238 | IF61: 239 | IG61: 240 | IH61: 241 | II61: 242 | IJ61: 243 | IK61: 244 | IL61: 245 | IM61: 246 | IN61: 247 | IO61: 248 | IP61: 249 | IQ61: 250 | IR61: 251 | IS61: 252 | IT61: 253 | IU61: 254 | IV61: 255 | IW61: 256 | IX61: 257 | IY61: 258 | IZ61: 259 | JA61: 260 | JB61: 261 | JC61: 262 | JD61: 263 | JE61: 264 | JF61: 265 | JG61: 266 | JH61: 267 | JI61: 268 | JJ61: 269 | JK61: 270 | JL61: 271 | JM61: 272 | JN61: 273 | JO61: 274 | JP61: 275 | JQ61: 276 | JR61: 277 | JS61: 278 | JT61: 279 | JU61: 280 | JV61: 281 | JW61: 282 | JX61: 283 | JY61: 284 | JZ61: 285 | KA61: 286 | KB61: 287 | KC61: 288 | KD61: 289 | KE61: 290 | KF61: 291 | KG61: 292 | KH61: 293 | KI61: 294 | KJ61: 295 | KK61: 296 | KL61: 297 | KM61: 298 | KN61: 299 | KO61: 300 | KP61: 301 | KQ61: 302 | KR61: 303 | KS61: 304 | KT61: 305 | KU61: 306 | KV61: 307 | KW61: 308 | KX61: 309 | KY61: 310 | KZ61: 311 | LA61: 312 | LB61: 313 | LC61: 314 | LD61: 315 | LE61: 316 | LF61: 317 | LG61: 318 | LH61: 319 | LI61: 320 | LJ61: 321 | LK61: 322 | LL61: 323 | LM61: 324 | LN61: 325 | LO61: 326 | LP61: 327 | LQ61: 328 | LR61: 329 | LS61: 330 | LT61: 331 | LU61: 332 | LV61: 333 | LW61: 334 | LX61: 335 | LY61: 336 | LZ61: 337 | MA61: 338 | MB61: 339 | MC61: 340 | MD61: 341 | ME61: 342 | MF61: 343 | MG61: 344 | MH61: 345 | MI61: 346 | MJ61: 347 | MK61: 348 | ML61: 349 | MM61: 350 | MN61: 351 | MO61: 352 | MP61: 353 | MQ61: 354 | MR61: 355 | MS61: 356 | MT61: 357 | MU61: 358 | MV61: 359 | MW61: 360 | MX61: 361 | MY61: 362 | MZ61: 363 | NA61: 364 | NB61: 365 | NC61: 366 | ND61: 367 | NE61: 368 | NF61: 369 | NG61: 370 | NH61: 371 | NI61: 372 | NJ61: 373 | NK61: 374 | NL61: 375 | NM61: 376 | NN61: 377 | NO61: 378 | NP61: 379 | NQ61: 380 | NR61: 381 | NS61: 382 | NT61: 383 | NU61: 384 | NV61: 385 | NW61: 386 | NX61: 387 | NY61: 388 | NZ61: 389 | OA61: 390 | OB61: 391 | OC61: 392 | OD61: 393 | OE61: 394 | OF61: 395 | OG61: 396 | OH61: 397 | OI61: 398 | OJ61: 399 | OK61: 400 | OL61: 401 | OM61: 402 | ON61: 403 | OO61: 404 | OP61: 405 | OQ61: 406 | OR61: 407 | OS61: 408 | OT61: 409 | OU61: 410 | OV61: 411 | OW61: 412 | OX61: 413 | OY61: 414 | OZ61: 415 | PA61: 416 | PB61: 417 | PC61: 418 | PD61: 419 | PE61: 420 | PF61: 421 | PG61: 422 | PH61: 423 | PI61: 424 | PJ61: 425 | PK61: 426 | PL61: 427 | PM61: 428 | PN61: 429 | PO61: 430 | PP61: 431 | PQ61: 432 | PR61: 433 | PS61: 434 | PT61: 435 | PU61: 436 | PV61: 437 | PW61: 438 | PX61: 439 | PY61: 440 | PZ61: 441 | QA61: 442 | QB61: 443 | QC61: 444 | QD61: 445 | QE61: 446 | QF61: 447 | QG61: 448 | QH61: 449 | QI61: 450 | QJ61: 451 | QK61: 452 | QL61: 453 | QM61: 454 | QN61: 455 | QO61: 456 | QP61: 457 | QQ61: 458 | QR61: 459 | QS61: 460 | QT61: 461 | QU61: 462 | QV61: 463 | QW61: 464 | QX61: 465 | QY61: 466 | QZ61: 467 | RA61: 468 | RB61: 469 | RC61: 470 | RD61: 471 | RE61: 472 | RF61: 473 | RG61: 474 | RH61: 475 | RI61: 476 | RJ61: 477 | RK61: 478 | RL61: 479 | RM61: 480 | RN61: 481 | RO61: 482 | RP61: 483 | RQ61: 484 | RR61: 485 | RS61: 486 | RT61: 487 | RU61: 488 | RV61: 489 | RW61: 490 | RX61: 491 | RY61: 492 | RZ61: 493 | SA61: 494 | SB61: 495 | SC61: 496 | SD61: 497 | SE61: 498 | SF61: 499 | SG61: 500 | SH61: 501 | SI61: 502 | SJ61: 503 | SK61: 504 | SL61: 505 | SM61: 506 | SN61: 507 | SO61: 508 | SP61: 509 | SQ61: 510 | SR61: 511 | SS61: 512 | ST61: 513 | SU61: 514 | SV61: 515 | SW61: 516 | SX61: 517 | SY61: 518 | SZ61: 519 | TA61: 520 | TB61: 521 | TC61: 522 | TD61: 523 | TE61: 524 | TF61: 525 | TG61: 526 | TH61: 527 | TI61: 528 | TJ61: 529 | TK61: 530 | TL61: 531 | TM61: 532 | TN61: 533 | TO61: 534 | TP61: 535 | TQ61: 536 | TR61: 537 | TS61: 538 | TT61: 539 | TU61: 540 | TV61: 541 | TW61: 542 | TX61: 543 | TY61: 544 | TZ61: 545 | UA61: 546 | UB61: 547 | UC61: 548 | UD61: 549 | UE61: 550 | UF61: 551 | UG61: 552 | UH61: 553 | UI61: 554 | UJ61: 555 | UK61: 556 | UL61: 557 | UM61: 558 | UN61: 559 | UO61: 560 | UP61: 561 | UQ61: 562 | UR61: 563 | US61: 564 | UT61: 565 | UU61: 566 | UV61: 567 | UW61: 568 | UX61: 569 | UY61: 570 | UZ61: 571 | VA61: 572 | VB61: 573 | VC61: 574 | VD61: 575 | VE61: 576 | VF61: 577 | VG61: 578 | VH61: 579 | VI61: 580 | VJ61: 581 | VK61: 582 | VL61: 583 | VM61: 584 | VN61: 585 | VO61: 586 | VP61: 587 | VQ61: 588 | VR61: 589 | VS61: 590 | VT61: 591 | VU61: 592 | VV61: 593 | VW61: 594 | VX61: 595 | VY61: 596 | VZ61: 597 | WA61: 598 | WB61: 599 | WC61: 600 | WD61: 601 | WE61: 602 | WF61: 603 | WG61: 604 | WH61: 605 | WI61: 606 | WJ61: 607 | WK61: 608 | WL61: 609 | WM61: 610 | WN61: 611 | WO61: 612 | WP61: 613 | WQ61: 614 | WR61: 615 | WS61: 616 | WT61: 617 | WU61: 618 | WV61: 619 | WW61: 620 | WX61: 621 | WY61: 622 | WZ61: 623 | XA61: 624 | XB61: 625 | XC61: 626 | XD61: 627 | XE61: 628 | XF61: 629 | XG61: 630 | XH61: 631 | XI61: 632 | XJ61: 633 | XK61: 634 | XL61: 635 | XM61: 636 | XN61: 637 | XO61: 638 | XP61: 639 | XQ61: 640 | XR61: 641 | XS61: 642 | XT61: 643 | XU61: 644 | XV61: 645 | XW61: 646 | XX61: 647 | XY61: 648 | XZ61: 649 | YA61: 650 | YB61: 651 | YC61: 652 | YD61: 653 | YE61: 654 | YF61: 655 | YG61: 656 | YH61: 657 | YI61: 658 | YJ61: 659 | YK61: 660 | YL61: 661 | YM61: 662 | YN61: 663 | YO61: 664 | YP61: 665 | YQ61: 666 | YR61: 667 | YS61: 668 | YT61: 669 | YU61: 670 | YV61: 671 | YW61: 672 | YX61: 673 | YY61: 674 | YZ61: 675 | ZA61: 676 | ZB61: 677 | ZC61: 678 | ZD61: 679 | ZE61: 680 | ZF61: 681 | ZG61: 682 | ZH61: 683 | ZI61: 684 | ZJ61: 685 | ZK61: 686 | ZL61: 687 | ZM61: 688 | ZN61: 689 | ZO61: 690 | ZP61: 691 | ZQ61: 692 | ZR61: 693 | ZS61: 694 | ZT61: 695 | ZU61: 696 | ZV61: 697 | ZW61: 698 | ZX61: 699 | ZY61: 700 | ZZ61: 701 | AAA61: 702 | AAB61: 703 | AAC61: 704 | AAD61: 705 | AAE61: 706 | AAF61: 707 | AAG61: 708 | AAH61: 709 | AAI61: 710 | AAJ61: 711 | AAK61: 712 | AAL61: 713 | AAM61: 714 | AAN61: 715 | AAO61: 716 | AAP61: 717 | AAQ61: 718 | AAR61: 719 | AAS61: 720 | AAT61: 721 | AAU61: 722 | AAV61: 723 | AAW61: 724 | AAX61: 725 | AAY61: 726 | AAZ61: 727 | ABA61: 728 | ABB61: 729 | ABC61: 730 | ABD61: 731 | ABE61: 732 | ABF61: 733 | ABG61: 734 | ABH61: 735 | ABI61: 736 | ABJ61: 737 | ABK61: 738 | ABL61: 739 | ABM61: 740 | ABN61: 741 | ABO61: 742 | ABP61: 743 | ABQ61: 744 | ABR61: 745 | ABS61: 746 | ABT61: 747 | ABU61: 748 | ABV61: 749 | ABW61: 750 | ABX61: 751 | ABY61: 752 | ABZ61: 753 | ACA61: 754 | ACB61: 755 | ACC61: 756 | ACD61: 757 | ACE61: 758 | ACF61: 759 | ACG61: 760 | ACH61: 761 | ACI61: 762 | ACJ61: 763 | ACK61: 764 | ACL61: 765 | ACM61: 766 | ACN61: 767 | ACO61: 768 | ACP61: 769 | ACQ61: 770 | ACR61: 771 | ACS61: 772 | ACT61: 773 | ACU61: 774 | ACV61: 775 | ACW61: 776 | ACX61: 777 | ACY61: 778 | ACZ61: 779 | ADA61: 780 | ADB61: 781 | ADC61: 782 | ADD61: 783 | ADE61: 784 | ADF61: 785 | ADG61: 786 | ADH61: 787 | ADI61: 788 | ADJ61: 789 | ADK61: 790 | ADL61: 791 | ADM61: 792 | ADN61: 793 | ADO61: 794 | ADP61: 795 | ADQ61: 796 | ADR61: 797 | ADS61: 798 | ADT61: 799 | ADU61: 800 | ADV61: 801 | ADW61: 802 | ADX61: 803 | ADY61: 804 | ADZ61: 805 | AEA61: 806 | AEB61: 807 | AEC61: 808 | AED61: 809 | AEE61: 810 | AEF61: 811 | AEG61: 812 | AEH61: 813 | AEI61: 814 | AEJ61: 815 | AEK61: 816 | AEL61: 817 | AEM61: 818 | AEN61: 819 | AEO61: 820 | AEP61: 821 | AEQ61: 822 | AER61: 823 | AES61: 824 | AET61: 825 | AEU61: 826 | AEV61: 827 | AEW61: 828 | AEX61: 829 | AEY61: 830 | AEZ61: 831 | AFA61: 832 | AFB61: 833 | AFC61: 834 | AFD61: 835 | AFE61: 836 | AFF61: 837 | AFG61: 838 | AFH61: 839 | AFI61: 840 | AFJ61: 841 | AFK61: 842 | AFL61: 843 | AFM61: 844 | AFN61: 845 | AFO61: 846 | AFP61: 847 | AFQ61: 848 | AFR61: 849 | AFS61: 850 | AFT61: 851 | AFU61: 852 | AFV61: 853 | AFW61: 854 | AFX61: 855 | AFY61: 856 | AFZ61: 857 | AGA61: 858 | AGB61: 859 | AGC61: 860 | AGD61: 861 | AGE61: 862 | AGF61: 863 | AGG61: 864 | AGH61: 865 | AGI61: 866 | AGJ61: 867 | AGK61: 868 | AGL61: 869 | AGM61: 870 | AGN61: 871 | AGO61: 872 | AGP61: 873 | AGQ61: 874 | AGR61: 875 | AGS61: 876 | AGT61: 877 | AGU61: 878 | AGV61: 879 | AGW61: 880 | AGX61: 881 | AGY61: 882 | AGZ61: 883 | AHA61: 884 | AHB61: 885 | AHC61: 886 | AHD61: 887 | AHE61: 888 | AHF61: 889 | AHG61: 890 | AHH61: 891 | AHI61: 892 | AHJ61: 893 | AHK61: 894 | AHL61: 895 | AHM61: 896 | AHN61: 897 | AHO61: 898 | AHP61: 899 | AHQ61: 900 | AHR61: 901 | AHS61: 902 | AHT61: 903 | AHU61: 904 | AHV61: 905 | AHW61: 906 | AHX61: 907 | AHY61: 908 | AHZ61: 909 | AIA61: 910 | AIB61: 911 | AIC61: 912 | AID61: 913 | AIE61: 914 | AIF61: 915 | AIG61: 916 | AIH61: 917 | AII61: 918 | AIJ61: 919 | AIK61: 920 | AIL61: 921 | AIM61: 922 | AIN61: 923 | AIO61: 924 | AIP61: 925 | AIQ61: 926 | AIR61: 927 | AIS61: 928 | AIT61: 929 | AIU61: 930 | AIV61: 931 | AIW61: 932 | AIX61: 933 | AIY61: 934 | AIZ61: 935 | AJA61: 936 | AJB61: 937 | AJC61: 938 | AJD61: 939 | AJE61: 940 | AJF61: 941 | AJG61: 942 | AJH61: 943 | AJI61: 944 | AJJ61: 945 | AJK61: 946 | AJL61: 947 | AJM61: 948 | AJN61: 949 | AJO61: 950 | AJP61: 951 | AJQ61: 952 | AJR61: 953 | AJS61: 954 | AJT61: 955 | AJU61: 956 | AJV61: 957 | AJW61: 958 | AJX61: 959 | AJY61: 960 | AJZ61: 961 | AKA61: 962 | AKB61: 963 | AKC61: 964 | AKD61: 965 | AKE61: 966 | AKF61: 967 | AKG61: 968 | AKH61: 969 | AKI61: 970 | AKJ61: 971 | AKK61: 972 | AKL61: 973 | AKM61: 974 | AKN61: 975 | AKO61: 976 | AKP61: 977 | AKQ61: 978 | AKR61: 979 | AKS61: 980 | AKT61: 981 | AKU61: 982 | AKV61: 983 | AKW61: 984 | AKX61: 985 | AKY61: 986 | AKZ61: 987 | ALA61: 988 | ALB61: 989 | ALC61: 990 | ALD61: 991 | ALE61: 992 | ALF61: 993 | ALG61: 994 | ALH61: 995 | ALI61: 996 | ALJ61: 997 | ALK61: 998 | ALL61: 999 | ALM61: 1000
A62: 30 | B62: =_xlfn.NORM.INV(RAND(),'Inflation Rates '!$B$401,'Inflation Rates '!$B$402) -> 2.2410518 | C62: 2.8064286 | D62: 0.34930637 | E62: 2.2425559 | F62: 1.6039553 | G62: 0.86049719 | H62: -0.43043507 | I62: 1.4869649 | J62: 0.11876842 | K62: -0.21001516 | L62: 1.722321 | M62: 1.8366166 | N62: 2.2891294 | O62: 1.4916 | P62: 2.4038586 | Q62: -0.74629447 | R62: 2.3413153 | S62: 2.1389674 | T62: -0.68473145 | U62: 0.96691833 | V62: 4.0165824 | W62: 1.7773232 | X62: -0.45873992 | Y62: 3.9020671 | Z62: 1.5764335 | AA62: 1.8943157 | AB62: 1.4707105 | AC62: 2.9178816 | AD62: 0.9496293 | AE62: 0.79440672 | AF62: 1.9815362 | AG62: 1.4364523 | AH62: 1.8219146 | AI62: 1.1945225 | AJ62: 1.9511012 | AK62: 4.3287142 | AL62: 3.1511915 | AM62: 1.867726 | AN62: 2.6161877 | AO62: 0.51070938 | AP62: 0.49317545 | AQ62: 3.5209181 | AR62: 0.58316743 | AS62: 1.6085217 | AT62: 1.8315847 | AU62: 2.703562 | AV62: 1.829345 | AW62: 2.0658202 | AX62: 0.22457294 | AY62: 6.7943165 | AZ62: -0.40475173 | BA62: 3.3623358 | BB62: 1.7196624 | BC62: 3.4690965 | BD62: 2.0126356 | BE62: 0.65329574 | BF62: 1.6154631 | BG62: 2.7783292 | BH62: 2.7685933 | BI62: 2.577419 | BJ62: 2.2019349 | BK62: 1.2778661 | BL62: 2.4259156 | BM62: 0.34574786 | BN62: 3.7392582 | BO62: -0.71870823 | BP62: 0.65134291 | BQ62: 3.1361564 | BR62: 1.2991118 | BS62: 0.82121049 | BT62: 1.0692665 | BU62: 3.2289502 | BV62: 3.9419809 | BW62: 0.50149206 | BX62: 2.3411128 | BY62: 1.7434007 | BZ62: 5.0084314 | CA62: 3.453857 | CB62: 3.0480291 | CC62: 1.2209322 | CD62: 0.84802999 | CE62: 2.6420834 | CF62: 2.7503376 | CG62: 2.6086812 | CH62: -0.46249577 | CI62: -0.082549634 | CJ62: 0.88474543 | CK62: 0.97166034 | CL62: 1.721115 | CM62: 2.6921752 | CN62: 1.5117768 | CO62: 0.11405815 | CP62: 1.0595542 | CQ62: 2.2986738 | CR62: 1.5876723 | CS62: 2.0015854 | CT62: 0.48033539 | CU62: 0.15218943 | CV62: 4.056499 | CW62: 1.4870345 | CX62: 2.7379658 | CY62: 2.340588 | CZ62: 1.1830565 | DA62: 1.8159882 | DB62: 0.76654101 | DC62: 1.3699655 | DD62: 3.1976179 | DE62: 1.5595175 | DF62: 3.5506289 | DG62: 3.3526414 | DH62: 0.36331097 | DI62: 1.4487909 | DJ62: 0.66924707 | DK62: 1.3182884 | DL62: 2.4440604 | DM62: 1.2078507 | DN62: 2.4551426 | DO62: 2.3498155 | DP62: 0.14625654 | DQ62: 3.3858355 | DR62: 1.198355 | DS62: 3.1479186 | DT62: 3.294223 | DU62: 0.63905533 | DV62: 0.1292471 | DW62: 3.8247069 | DX62: 1.5922337 | DY62: 1.2088299 | DZ62: 2.7496686 | EA62: 3.6948309 | EB62: 1.9248603 | EC62: 2.5508115 | ED62: 0.68644448 | EE62: 1.6150515 | EF62: 2.6858552 | EG62: 2.6453201 | EH62: 2.0986133 | EI62: -0.62378794 | EJ62: 2.4567986 | EK62: 0.8971159 | EL62: 0.85000476 | EM62: 0.69121169 | EN62: 0.99630547 | EO62: 2.0791935 | EP62: -0.73849113 | EQ62: -0.80495311 | ER62: 2.0798146 | ES62: 1.1243353 | ET62: 3.051876 | EU62: 2.8274221 | EV62: 1.7301703 | EW62: 1.8465611 | EX62: 0.27484769 | EY62: 0.5447721 | EZ62: 1.4081994 | FA62: 0.58596485 | FB62: 3.8163695 | FC62: 1.4946305 | FD62: 2.0867851 | FE62: 0.82844059 | FF62: 3.0211924 | FG62: 2.8018061 | FH62: 2.6368691 | FI62: 1.4453768 | FJ62: 1.6686764 | FK62: 0.35699983 | FL62: 1.9704593 | FM62: 2.4391696 | FN62: 3.6761505 | FO62: 2.1650529 | FP62: 2.23256 | FQ62: 2.8166154 | FR62: 1.3814788 | FS62: 0.26189581 | FT62: 0.72589228 | FU62: 0.70894479 | FV62: 1.9599248 | FW62: 1.7922179 | FX62: -0.12317297 | FY62: -0.098762949 | FZ62: 3.4920514 | GA62: 2.0650802 | GB62: 1.7545181 | GC62: 2.0803045 | GD62: 1.4826007 | GE62: 1.1850438 | GF62: 2.9332698 | GG62: 1.263613 | GH62: 0.42038525 | GI62: 0.23472109 | GJ62: 2.2690176 | GK62: 2.5735097 | GL62: 1.129622 | GM62: 3.2484881 | GN62: 1.0529686 | GO62: 3.4090579 | GP62: 1.8808984 | GQ62: -0.22998023 | GR62: 3.2484685 | GS62: 1.6466301 | GT62: 1.2265277 | GU62: 1.0732159 | GV62: 2.5508483 | GW62: 1.5768811 | GX62: 1.4857421 | GY62: 2.4500959 | GZ62: 2.7344643 | HA62: 3.3614159 | HB62: 0.34849959 | HC62: 1.1788561 | HD62: 0.3923123 | HE62: 1.971004 | HF62: 2.8803309 | HG62: 0.68560898 | HH62: 2.4703183 | HI62: 2.083174 | HJ62: 0.7951956 | HK62: 0.89841226 | HL62: 3.2551553 | HM62: 3.7634788 | HN62: -0.93635893 | HO62: 0.71265664 | HP62: 2.7836506 | HQ62: 2.1960151 | HR62: 3.9380131 | HS62: 0.38500528 | HT62: 0.33642369 | HU62: 2.7281599 | HV62: 2.8482404 | HW62: 2.331065 | HX62: 0.80855562 | HY62: 3.3091697 | HZ62: 1.7626107 | IA62: -0.47189338 | IB62: 1.5321656 | IC62: 0.94088476 | ID62: 0.22281772 | IE62: 1.9530181 | IF62: 1.825232 | IG62: 1.6953794 | IH62: 2.9914159 | II62: 0.82217402 | IJ62: 4.5934403 | IK62: 0.32097136 | IL62: 3.3487204 | IM62: 1.6822517 | IN62: 3.3270777 | IO62: 0.59296441 | IP62: -0.75814941 | IQ62: 2.5418437 | IR62: 1.6723008 | IS62: -0.82978059 | IT62: 1.0765144 | IU62: 1.1015396 | IV62: 1.0609312 | IW62: 1.6608134 | IX62: 3.6401775 | IY62: 1.5735224 | IZ62: 0.96974222 | JA62: 2.7228328 | JB62: 0.58477442 | JC62: 2.1815409 | JD62: 2.4038108 | JE62: 2.8990861 | JF62: 1.0661218 | JG62: 1.6751646 | JH62: 0.66997316 | JI62: 2.3309149 | JJ62: 2.5868293 | JK62: 1.579207 | JL62: 1.3170569 | JM62: 2.9567261 | JN62: -0.088511742 | JO62: 1.7788421 | JP62: 0.96662926 | JQ62: 0.63987932 | JR62: 2.6477745 | JS62: 2.9818408 | JT62: -0.47129661 | JU62: 0.99292442 | JV62: 1.8737501 | JW62: 1.7269179 | JX62: 1.3454372 | JY62: 0.92271824 | JZ62: 0.86768606 | KA62: 2.8619078 | KB62: 3.0436188 | KC62: 2.2210964 | KD62: 2.0726862 | KE62: 2.0982607 | KF62: -0.1064855 | KG62: 0.54024911 | KH62: 0.67157338 | KI62: 1.0078143 | KJ62: 2.8621438 | KK62: 1.8732757 | KL62: 2.9300915 | KM62: 1.5276826 | KN62: 2.1135551 | KO62: 1.4331358 | KP62: 3.0561794 | KQ62: 0.92576414 | KR62: -0.085299916 | KS62: 1.8899534 | KT62: -0.51332593 | KU62: 2.7852356 | KV62: 3.38189 | KW62: 1.3632188 | KX62: 1.9198315 | KY62: 1.7201221 | KZ62: 2.1303848 | LA62: 1.9886732 | LB62: 2.7989986 | LC62: 2.4422025 | LD62: 1.9942642 | LE62: 1.3630191 | LF62: 1.5580806 | LG62: 1.7361767 | LH62: 3.6211535 | LI62: 0.093728435 | LJ62: -0.6790302 | LK62: 2.3295304 | LL62: 3.4661265 | LM62: 2.0024404 | LN62: 0.065799082 | LO62: 2.9088235 | LP62: 0.77104826 | LQ62: 1.2454294 | LR62: 2.0439243 | LS62: 1.4242593 | LT62: 1.415152 | LU62: 2.3080599 | LV62: 1.6874149 | LW62: 3.1880142 | LX62: 1.2084311 | LY62: 0.78013398 | LZ62: 0.64989521 | MA62: -0.084203134 | MB62: 2.5930967 | MC62: 1.0569353 | MD62: 1.5418335 | ME62: 0.68658877 | MF62: 2.2526272 | MG62: 0.79700137 | MH62: 2.697709 | MI62: 0.7474443 | MJ62: 1.3534004 | MK62: 2.2500789 | ML62: 4.4663465 | MM62: 3.087707 | MN62: 1.7302428 | MO62: 1.2313681 | MP62: 1.5673722 | MQ62: 1.3138925 | MR62: 1.0507277 | MS62: 2.0242005 | MT62: 2.125084 | MU62: 0.68110749 | MV62: 2.2125758 | MW62: 2.6460183 | MX62: 1.3870113 | MY62: 1.9183138 | MZ62: 2.5672694 | NA62: 2.7151795 | NB62: 0.64531297 | NC62: -1.3057249 | ND62: 0.84308083 | NE62: 1.4311519 | NF62: 1.3168108 | NG62: 3.1318364 | NH62: 3.5778176 | NI62: 1.7879998 | NJ62: 0.97405729 | NK62: 3.3452533 | NL62: 3.5454466 | NM62: -0.38483423 | NN62: 1.4157437 | NO62: -0.12666388 | NP62: 0.59925497 | NQ62: 2.1557869 | NR62: 0.80713275 | NS62: 3.2998069 | NT62: 1.7532549 | NU62: 0.2054903 | NV62: 1.2212321 | NW62: 0.08705159 | NX62: 1.1778911 | NY62: 1.8800719 | NZ62: 1.6846679 | OA62: 0.22304568 | OB62: 0.59666505 | OC62: 4.1644053 | OD62: 2.2613183 | OE62: 1.820716 | OF62: 2.1430732 | OG62: 2.0569459 | OH62: 1.1461929 | OI62: 2.0742851 | OJ62: 2.3190446 | OK62: 1.2112461 | OL62: 1.3957584 | OM62: -1.0205992 | ON62: 1.3745935 | OO62: 1.337382 | OP62: 2.1582093 | OQ62: -0.13208121 | OR62: 2.4072755 | OS62: -0.093587554 | OT62: 0.48534419 | OU62: 2.2839342 | OV62: 3.6515995 | OW62: 1.569927 | OX62: 2.9397174 | OY62: 0.75071983 | OZ62: 0.82895214 | PA62: 3.3194322 | PB62: 4.55031 | PC62: 2.6437746 | PD62: 1.1754124 | PE62: 0.52431278 | PF62: 1.690926 | PG62: 1.637545 | PH62: 2.5230606 | PI62: -1.4714595 | PJ62: 2.2731853 | PK62: 3.947601 | PL62: 0.44453244 | PM62: 2.4854705 | PN62: 0.47054285 | PO62: 0.55141061 | PP62: 2.3142492 | PQ62: 2.0476485 | PR62: 1.9349394 | PS62: 3.7933326 | PT62: 0.32160446 | PU62: 1.7538095 | PV62: 1.05148 | PW62: -0.0020394095 | PX62: 0.93189301 | PY62: 0.95079993 | PZ62: -0.7657874 | QA62: 3.0367167 | QB62: 2.9407873 | QC62: 1.9719621 | QD62: 0.61301924 | QE62: 1.9675765 | QF62: 0.27014239 | QG62: 3.6500139 | QH62: 0.91824759 | QI62: 1.8517809 | QJ62: 0.33155967 | QK62: 1.3547318 | QL62: 2.4776887 | QM62: 2.9394666 | QN62: 0.18867224 | QO62: 3.244636 | QP62: 2.5236467 | QQ62: -0.36672207 | QR62: 2.6302971 | QS62: 1.9881807 | QT62: 3.1187268 | QU62: 0.42696866 | QV62: 2.2911259 | QW62: 4.1180507 | QX62: -0.42680467 | QY62: 0.93839714 | QZ62: 0.35566617 | RA62: 1.1044821 | RB62: 0.2636218 | RC62: 2.6701541 | RD62: 2.736372 | RE62: 4.0934155 | RF62: 2.8642052 | RG62: 0.77983897 | RH62: 2.0886108 | RI62: 2.1290585 | RJ62: 2.1980932 | RK62: 0.016481844 | RL62: -0.01961914 | RM62: 1.2395383 | RN62: 1.7627043 | RO62: 1.71089 | RP62: 1.2271991 | RQ62: 0.86678296 | RR62: 1.1806879 | RS62: 2.9315262 | RT62: 2.22189 | RU62: 2.3024669 | RV62: -0.70869517 | RW62: 3.7477795 | RX62: 1.9659429 | RY62: 2.2918887 | RZ62: 1.7593294 | SA62: 1.5081867 | SB62: 1.979235 | SC62: 3.3177218 | SD62: 1.2034682 | SE62: 1.846605 | SF62: 3.9928617 | SG62: 1.9830291 | SH62: 1.8075805 | SI62: 2.1937646 | SJ62: 0.75957707 | SK62: 3.0722408 | SL62: 3.2955242 | SM62: 1.3402845 | SN62: 2.889379 | SO62: 2.1663389 | SP62: 3.4378874 | SQ62: -0.82411523 | SR62: 1.6776472 | SS62: 0.086741472 | ST62: 0.52907299 | SU62: 1.3856468 | SV62: 0.8563856 | SW62: 0.61611439 | SX62: 1.1765884 | SY62: 0.30304533 | SZ62: 2.1107771 | TA62: 2.81876 | TB62: 3.0924544 | TC62: 0.70593875 | TD62: 0.063549488 | TE62: 3.0536314 | TF62: 1.6822793 | TG62: 1.6479142 | TH62: 1.0301397 | TI62: 2.9896229 | TJ62: 1.210286 | TK62: 2.1862914 | TL62: 2.0301014 | TM62: 1.1788623 | TN62: 1.6476247 | TO62: 2.2629944 | TP62: 4.3847206 | TQ62: -0.897611 | TR62: 1.6660331 | TS62: 0.83815435 | TT62: 1.849507 | TU62: 2.0685098 | TV62: 1.6580703 | TW62: 2.9081359 | TX62: 1.8300059 | TY62: 2.3971299 | TZ62: 1.5431243 | UA62: 1.7855276 | UB62: 3.1218125 | UC62: 3.5523859 | UD62: 1.8436273 | UE62: -0.42141081 | UF62: 1.8549446 | UG62: 1.3017532 | UH62: 3.0912563 | UI62: 3.4600112 | UJ62: 0.19129074 | UK62: 1.691619 | UL62: 1.8750054 | UM62: 3.2398379 | UN62: 0.51568278 | UO62: 1.8427594 | UP62: 2.2385279 | UQ62: 2.8013574 | UR62: 0.0096648563 | US62: 3.0187869 | UT62: 1.7775725 | UU62: 1.593094 | UV62: 0.83411111 | UW62: 2.3335569 | UX62: 2.8558001 | UY62: 1.0954355 | UZ62: 0.41150473 | VA62: 1.6494716 | VB62: 1.9410554 | VC62: 3.2637213 | VD62: 2.5420848 | VE62: -0.44239811 | VF62: 2.0152965 | VG62: -0.17260038 | VH62: 0.29912637 | VI62: 1.651444 | VJ62: 2.7590162 | VK62: 1.9364484 | VL62: 0.63682654 | VM62: 0.054703639 | VN62: 2.5452265 | VO62: 1.5225992 | VP62: 3.1655019 | VQ62: 3.0657468 | VR62: -0.15306505 | VS62: 1.1093479 | VT62: 1.1917258 | VU62: 1.9659627 | VV62: -0.73838361 | VW62: 1.9845999 | VX62: 2.4613264 | VY62: 0.7789518 | VZ62: 1.2888563 | WA62: 1.9129549 | WB62: 0.88759667 | WC62: 0.69268623 | WD62: 0.33288509 | WE62: 1.5043043 | WF62: 1.59871 | WG62: 0.67365893 | WH62: 2.6078393 | WI62: 1.9796915 | WJ62: -0.11103162 | WK62: 1.2996896 | WL62: 0.96474906 | WM62: 3.6372235 | WN62: 2.2841902 | WO62: 3.0421172 | WP62: 1.0768251 | WQ62: -0.52390458 | WR62: 2.4207144 | WS62: 0.35857653 | WT62: 0.68296427 | WU62: 2.4815421 | WV62: 4.3077044 | WW62: 1.691771 | WX62: -0.73931085 | WY62: 1.5532835 | WZ62: 2.2147002 | XA62: 3.1810496 | XB62: 3.7648221 | XC62: 1.2037443 | XD62: 2.8717451 | XE62: 2.9365987 | XF62: 3.0820841 | XG62: 1.1308097 | XH62: 1.8178292 | XI62: -0.96074927 | XJ62: 3.0533976 | XK62: 1.0866201 | XL62: 0.086023273 | XM62: 0.21801698 | XN62: 2.3507584 | XO62: 1.4666581 | XP62: -0.16204889 | XQ62: 1.0536268 | XR62: 1.6607284 | XS62: 2.3220249 | XT62: 3.2662722 | XU62: 1.4978108 | XV62: 2.5268181 | XW62: 0.14040319 | XX62: 1.6763803 | XY62: -0.025064579 | XZ62: -0.52444859 | YA62: 2.7114674 | YB62: 3.036812 | YC62: 1.3600057 | YD62: 1.3825811 | YE62: 4.9376578 | YF62: 2.2237461 | YG62: 2.0129222 | YH62: 0.95750528 | YI62: 1.8282566 | YJ62: 4.0724482 | YK62: 2.1998181 | YL62: 1.1841267 | YM62: 1.9748492 | YN62: 1.5295105 | YO62: 1.7679191 | YP62: 1.5785092 | YQ62: 0.63990978 | YR62: 2.4525412 | YS62: 0.36250195 | YT62: 0.80250539 | YU62: 1.1822603 | YV62: 1.9532589 | YW62: 1.9712213 | YX62: 1.8551237 | YY62: 3.5853595 | YZ62: 2.6369356 | ZA62: 2.1869329 | ZB62: 1.1008545 | ZC62: 1.2023695 | ZD62: 2.0162177 | ZE62: 0.99957983 | ZF62: 1.5601255 | ZG62: 0.012081889 | ZH62: 0.59860779 | ZI62: 3.6645531 | ZJ62: 2.4100941 | ZK62: 2.0359336 | ZL62: 1.7893886 | ZM62: 0.51063493 | ZN62: 2.0615076 | ZO62: 0.007252509 | ZP62: 0.95383674 | ZQ62: 2.1486894 | ZR62: 0.39349402 | ZS62: 0.11668211 | ZT62: 2.313324 | ZU62: 3.6005282 | ZV62: 2.7892328 | ZW62: 0.204763 | ZX62: 2.8545623 | ZY62: -0.6047777 | ZZ62: 1.1485717 | AAA62: 2.4947032 | AAB62: 1.1792455 | AAC62: 2.8476324 | AAD62: 1.8017273 | AAE62: 1.5353293 | AAF62: 0.82726973 | AAG62: 0.36728203 | AAH62: 2.9279802 | AAI62: 1.4413681 | AAJ62: 1.5443504 | AAK62: 1.6453242 | AAL62: 1.4057068 | AAM62: 1.5661469 | AAN62: 2.9932804 | AAO62: 2.2894704 | AAP62: 3.6645207 | AAQ62: 2.8118317 | AAR62: 0.11449066 | AAS62: 2.1109169 | AAT62: 0.50731576 | AAU62: 3.5301849 | AAV62: 2.8810822 | AAW62: 2.6484812 | AAX62: 2.2735783 | AAY62: 1.2918373 | AAZ62: 2.0404385 | ABA62: 1.5917741 | ABB62: 0.79940665 | ABC62: 0.32178436 | ABD62: 3.5671665 | ABE62: 0.77508513 | ABF62: 3.2851092 | ABG62: 1.7033689 | ABH62: 2.1120967 | ABI62: 0.86190929 | ABJ62: 3.6210647 | ABK62: 2.7352875 | ABL62: 1.6974277 | ABM62: 0.81454856 | ABN62: 1.2513831 | ABO62: 2.575818 | ABP62: 1.6762989 | ABQ62: 2.5579083 | ABR62: 2.8348519 | ABS62: 2.4209973 | ABT62: 2.7081242 | ABU62: 2.6435698 | ABV62: 1.3014076 | ABW62: 3.0686622 | ABX62: 0.74696951 | ABY62: 0.77829538 | ABZ62: 1.4445336 | ACA62: 0.70040534 | ACB62: 0.84564194 | ACC62: 2.1722651 | ACD62: 1.5948487 | ACE62: 1.0477161 | ACF62: 3.7264125 | ACG62: 3.0060286 | ACH62: 1.9088624 | ACI62: 2.0038973 | ACJ62: 2.5216775 | ACK62: 0.62489567 | ACL62: 1.9134555 | ACM62: 2.4695557 | ACN62: 1.8122446 | ACO62: 2.7954094 | ACP62: -1.4087845 | ACQ62: 1.7055863 | ACR62: 1.4953362 | ACS62: 0.79708679 | ACT62: 0.88503889 | ACU62: 0.28090852 | ACV62: 0.93782798 | ACW62: 1.7379599 | ACX62: 3.181027 | ACY62: 1.036859 | ACZ62: 0.45076701 | ADA62: 2.8952273 | ADB62: 1.0167731 | ADC62: 2.2333422 | ADD62: 0.53095609 | ADE62: 1.6719908 | ADF62: 1.0233105 | ADG62: 3.2284834 | ADH62: 1.3244259 | ADI62: 2.159803 | ADJ62: 2.4049781 | ADK62: 2.1663966 | ADL62: 1.1847333 | ADM62: 1.1705504 | ADN62: 1.0759487 | ADO62: 2.1461943 | ADP62: 2.2547022 | ADQ62: 1.0376059 | ADR62: 0.72066255 | ADS62: 1.3726148 | ADT62: -0.24234277 | ADU62: 2.734324 | ADV62: 5.0313816 | ADW62: 1.4161032 | ADX62: 2.2487142 | ADY62: 0.89943648 | ADZ62: 2.4931075 | AEA62: 2.6361878 | AEB62: 1.5998861 | AEC62: 1.1573524 | AED62: 0.632918 | AEE62: 1.9268835 | AEF62: 2.2626094 | AEG62: 2.2615686 | AEH62: 0.5999487 | AEI62: 4.9085359 | AEJ62: 1.6719619 | AEK62: 1.0045998 | AEL62: 1.4346437 | AEM62: 1.6168687 | AEN62: -0.22109938 | AEO62: 2.6598726 | AEP62: 2.4606624 | AEQ62: 0.67581122 | AER62: 3.238433 | AES62: 0.13689142 | AET62: 0.00052707262 | AEU62: -0.12487787 | AEV62: 1.1091478 | AEW62: 1.2127938 | AEX62: 2.1246481 | AEY62: 3.4527164 | AEZ62: 0.5795169 | AFA62: 1.8372098 | AFB62: 2.467539 | AFC62: 1.189236 | AFD62: 2.9288725 | AFE62: 1.8193691 | AFF62: 0.6103434 | AFG62: 2.0881376 | AFH62: 1.2404332 | AFI62: -1.4291906 | AFJ62: 1.9768991 | AFK62: 2.5505474 | AFL62: 1.2176033 | AFM62: 2.19773 | AFN62: 0.4268426 | AFO62: 1.3070604 | AFP62: 2.6528602 | AFQ62: 2.9240949 | AFR62: 0.18675905 | AFS62: 2.7350044 | AFT62: 1.2574554 | AFU62: 2.9588737 | AFV62: 2.0829721 | AFW62: 2.321865 | AFX62: 2.8545425 | AFY62: 3.6810761 | AFZ62: 1.8632964 | AGA62: 3.9596911 | AGB62: -0.55171666 | AGC62: 1.4690095 | AGD62: 4.7797884 | AGE62: 1.5251529 | AGF62: 0.84772817 | AGG62: -0.10030493 | AGH62: 1.9186487 | AGI62: 3.1204477 | AGJ62: 2.3155891 | AGK62: 2.9231796 | AGL62: 2.6586459 | AGM62: 2.8702238 | AGN62: 1.1541628 | AGO62: 0.91054815 | AGP62: 1.5708261 | AGQ62: 2.2408888 | AGR62: 1.9912742 | AGS62: 1.2922873 | AGT62: 2.2266376 | AGU62: 3.8054055 | AGV62: 3.2729492 | AGW62: 1.856728 | AGX62: 2.6651495 | AGY62: 1.5201533 | AGZ62: 1.092092 | AHA62: 1.4852004 | AHB62: 1.4719514 | AHC62: 2.0662745 | AHD62: 1.6472167 | AHE62: 0.41125148 | AHF62: 1.5085264 | AHG62: 1.8943347 | AHH62: 2.4724697 | AHI62: 3.2918326 | AHJ62: 1.9677178 | AHK62: 1.0567045 | AHL62: 1.4383015 | AHM62: 1.1805305 | AHN62: 3.009304 | AHO62: 2.1676819 | AHP62: 0.43117422 | AHQ62: 3.1095749 | AHR62: 2.9878569 | AHS62: 0.65924384 | AHT62: 1.3091541 | AHU62: 1.4964185 | AHV62: -1.9940332 | AHW62: 1.4760523 | AHX62: 2.4737066 | AHY62: 1.2236031 | AHZ62: 2.295552 | AIA62: 3.5400076 | AIB62: 0.29747686 | AIC62: -1.306493 | AID62: 1.6311195 | AIE62: 1.3082873 | AIF62: -0.59994729 | AIG62: 1.287332 | AIH62: 1.2560263 | AII62: 2.5492904 | AIJ62: 1.3535201 | AIK62: 3.3932119 | AIL62: 1.2077028 | AIM62: 3.2484898 | AIN62: 3.6891525 | AIO62: 3.2886015 | AIP62: 0.44476636 | AIQ62: 1.9124302 | AIR62: 0.6197659 | AIS62: 1.7336512 | AIT62: 3.4208124 | AIU62: 0.4441535 | AIV62: 1.657727 | AIW62: 1.3806193 | AIX62: 0.99967941 | AIY62: 1.3260033 | AIZ62: 3.4792777 | AJA62: 1.443958 | AJB62: 3.6737374 | AJC62: 1.949942 | AJD62: 0.3676505 | AJE62: 2.9460296 | AJF62: 1.6878621 | AJG62: 1.5246588 | AJH62: -0.17097697 | AJI62: 2.0798506 | AJJ62: 2.9821852 | AJK62: 2.3380421 | AJL62: 3.0553604 | AJM62: 2.2628887 | AJN62: 1.9667041 | AJO62: 2.8126858 | AJP62: 1.0021788 | AJQ62: 1.04737 | AJR62: 4.0450186 | AJS62: 1.1438146 | AJT62: 3.4961508 | AJU62: 1.9092647 | AJV62: 0.26024528 | AJW62: -0.88230009 | AJX62: 1.716488 | AJY62: 3.1799613 | AJZ62: 1.9547 | AKA62: 1.868267 | AKB62: 0.60498588 | AKC62: -0.97671756 | AKD62: 1.3083859 | AKE62: 1.2681688 | AKF62: 1.7112154 | AKG62: 1.4856055 | AKH62: 0.97273307 | AKI62: -0.15116114 | AKJ62: 1.9516423 | AKK62: 2.4381421 | AKL62: 2.1660318 | AKM62: 1.4726144 | AKN62: 0.71975334 | AKO62: 2.2197914 | AKP62: 0.32297701 | AKQ62: 1.6909394 | AKR62: 0.98463369 | AKS62: 3.4046449 | AKT62: 0.71006021 | AKU62: 2.1141105 | AKV62: 2.9717078 | AKW62: 1.8154336 | AKX62: 1.9720168 | AKY62: 0.37383401 | AKZ62: 2.1147144 | ALA62: 0.13808953 | ALB62: 0.92420188 | ALC62: 1.4760878 | ALD62: 1.4543301 | ALE62: 1.49884 | ALF62: 0.76935491 | ALG62: 1.3800302 | ALH62: 1.3826525 | ALI62: 4.1048491 | ALJ62: -0.11649298 | ALK62: 1.6049693 | ALL62: 0.69002921 | ALM62: 2.4566105
A63: 31 | B63: =_xlfn.NORM.INV(RAND(),'Inflation Rates '!$B$401,'Inflation Rates '!$B$402) -> 3.0639434 | C63: 3.2827038 | D63: 1.5540832 | E63: 1.0904728 | F63: 1.0032551 | G63: 0.78228814 | H63: 1.5169672 | I63: 1.0024894 | J63: 1.1540737 | K63: -0.19055344 | L63: 1.4192897 | M63: -1.1018369 | N63: 3.2186672 | O63: 1.1942484 | P63: 0.16088683 | Q63: 1.5869591 | R63: 1.825116 | S63: -0.24659902 | T63: 1.0935446 | U63: -0.19590899 | V63: -0.076619284 | W63: 1.7430394 | X63: 0.92728052 | Y63: 0.42153436 | Z63: -0.19439841 | AA63: 3.4227803 | AB63: 1.8808497 | AC63: 0.96472317 | AD63: 2.5729464 | AE63: -0.1609105 | AF63: 1.3734125 | AG63: -0.055474526 | AH63: 1.7094573 | AI63: 2.761682 | AJ63: 2.2492158 | AK63: 2.2698968 | AL63: 4.247476 | AM63: 0.99799447 | AN63: 2.8975998 | AO63: 2.2454039 | AP63: 0.46215668 | AQ63: 0.52431546 | AR63: 2.2917331 | AS63: 0.31968749 | AT63: 1.5518139 | AU63: 0.99390825 | AV63: 1.8849577 | AW63: 2.1163695 | AX63: 1.7277376 | AY63: 2.2400395 | AZ63: 2.577451 | BA63: 0.12952601 | BB63: 0.50256613 | BC63: 2.661652 | BD63: 2.6886492 | BE63: 2.5362167 | BF63: 2.7620823 | BG63: 1.9020728 | BH63: 3.3030892 | BI63: 1.7924719 | BJ63: 1.0083963 | BK63: 2.2722298 | BL63: 0.75262231 | BM63: 1.9935187 | BN63: 1.7633302 | BO63: -0.48405234 | BP63: 2.8146644 | BQ63: 2.5748485 | BR63: 1.9508231 | BS63: 2.1854814 | BT63: 3.7227544 | BU63: 2.3759165 | BV63: -0.099308107 | BW63: 1.9131427 | BX63: 3.889562 | BY63: -0.21058689 | BZ63: 2.7048501 | CA63: 0.79387797 | CB63: 1.5989285 | CC63: 1.7165707 | CD63: 2.5111947 | CE63: 4.044202 | CF63: 4.002625 | CG63: 0.39932317 | CH63: 1.5357295 | CI63: 0.98734881 | CJ63: 2.2187231 | CK63: 3.2880846 | CL63: 1.6745895 | CM63: 1.9859186 | CN63: 1.6398614 | CO63: 0.82954523 | CP63: 2.3700022 | CQ63: 0.9875149 | CR63: 2.9326359 | CS63: 2.5248752 | CT63: 1.808842 | CU63: 2.4091276 | CV63: 2.670934 | CW63: 1.0538045 | CX63: 2.2341889 | CY63: 1.3670633 | CZ63: 1.3303861 | DA63: -0.68350108 | DB63: 1.6015739 | DC63: 1.0151352 | DD63: 3.3374675 | DE63: 2.7973621 | DF63: 0.094451974 | DG63: 2.0286145 | DH63: 4.4493098 | DI63: 2.56002 | DJ63: 1.9657708 | DK63: 2.3671166 | DL63: 1.1298344 | DM63: 3.0486066 | DN63: 1.8686317 | DO63: 0.35326072 | DP63: 0.3967143 | DQ63: 1.8051552 | DR63: 1.4715883 | DS63: 1.3331259 | DT63: 0.33104249 | DU63: 0.91856011 | DV63: -0.58109915 | DW63: 2.1524538 | DX63: -2.1365546 | DY63: 0.032952436 | DZ63: 1.2762418 | EA63: 1.1009581 | EB63: 1.5668335 | EC63: 1.6176776 | ED63: 2.8515068 | EE63: 0.39872122 | EF63: 2.3859967 | EG63: 1.4055051 | EH63: 0.79145872 | EI63: 0.17535478 | EJ63: 1.9177554 | EK63: -0.87486014 | EL63: 1.0602761 | EM63: 0.23226927 | EN63: 0.36535812 | EO63: 0.80497484 | EP63: 2.2009546 | EQ63: 4.0917156 | ER63: 3.2739754 | ES63: 0.84718019 | ET63: 0.38419225 | EU63: 1.7672679 | EV63: -0.18668598 | EW63: 3.2903815 | EX63: 1.7467621 | EY63: 2.0891547 | EZ63: 2.5472082 | FA63: 2.2348674 | FB63: 1.1829359 | FC63: 2.1064149 | FD63: 1.9938739 | FE63: -0.53004964 | FF63: 2.5710184 | FG63: 2.0788184 | FH63: 2.5026908 | FI63: 2.2512402 | FJ63: 2.4299521 | FK63: 1.5632625 | FL63: 1.4026094 | FM63: 1.8339261 | FN63: 3.4128773 | FO63: 0.38219785 | FP63: 1.5855931 | FQ63: -0.64008245 | FR63: 2.3437926 | FS63: 1.1415943 | FT63: 3.3685858 | FU63: 1.6725184 | FV63: 0.95287743 | FW63: 0.23266727 | FX63: 2.4081368 | FY63: 2.6045966 | FZ63: 2.25746 | GA63: 3.0750283 | GB63: 0.83627351 | GC63: 1.0747607 | GD63: 3.2590873 | GE63: 1.8703463 | GF63: 2.2700623 | GG63: 2.0932659 | GH63: 2.0362601 | GI63: 0.13046647 | GJ63: -0.5570033 | GK63: 2.1697153 | GL63: 1.9468584 | GM63: 2.7074376 | GN63: 2.883755 | GO63: 1.7159076 | GP63: 2.2851296 | GQ63: 0.7680064 | GR63: 0.19935258 | GS63: 1.6637704 | GT63: 0.26905261 | GU63: 3.5780956 | GV63: 0.31102928 | GW63: 3.7710355 | GX63: 1.1957186 | GY63: 3.6128788 | GZ63: 3.3935566 | HA63: 0.80272374 | HB63: 0.82894173 | HC63: 1.1881573 | HD63: 0.87947445 | HE63: 0.14150228 | HF63: 2.5621884 | HG63: 0.48024663 | HH63: 1.8117702 | HI63: 3.2583539 | HJ63: 1.8045925 | HK63: -0.31285384 | HL63: 3.2310541 | HM63: 2.3487733 | HN63: -0.040389489 | HO63: 3.6064581 | HP63: 1.3958671 | HQ63: 1.6670532 | HR63: 1.8769817 | HS63: 1.7546215 | HT63: 1.9437856 | HU63: 2.1459618 | HV63: 2.5869203 | HW63: 3.7281244 | HX63: 1.9190559 | HY63: 1.3685674 | HZ63: 1.368287 | IA63: 0.26365133 | IB63: 1.023382 | IC63: 2.1751452 | ID63: 3.6936058 | IE63: 1.0640732 | IF63: -0.008677799 | IG63: 2.6974897 | IH63: 4.7407649 | II63: 1.0218944 | IJ63: 2.2619873 | IK63: 3.1075112 | IL63: -0.19447089 | IM63: 2.0832278 | IN63: 1.9622934 | IO63: 1.8961428 | IP63: 2.3979961 | IQ63: 0.98158626 | IR63: 0.99256983 | IS63: 1.9317272 | IT63: -0.264897 | IU63: 0.83900208 | IV63: 4.0600008 | IW63: 3.8931789 | IX63: 0.41257108 | IY63: 1.1716273 | IZ63: 1.9397326 | JA63: -0.21032529 | JB63: 1.4117173 | JC63: 0.84123405 | JD63: 2.3191792 | JE63: 3.3202188 | JF63: 2.6497491 | JG63: 2.1356146 | JH63: 1.5624517 | JI63: 3.830253 | JJ63: 0.28240599 | JK63: 2.2155027 | JL63: 1.3266186 | JM63: 1.1287606 | JN63: -0.43055378 | JO63: 0.51310667 | JP63: 0.43377686 | JQ63: 4.3287723 | JR63: 2.9773795 | JS63: 0.74483917 | JT63: 2.2177763 | JU63: 0.010000083 | JV63: 2.9324852 | JW63: 2.6746242 | JX63: 0.41542678 | JY63: 0.13326197 | JZ63: 0.34696871 | KA63: 1.6427858 | KB63: 2.6645797 | KC63: 2.8348404 | KD63: 2.6743223 | KE63: 2.8369589 | KF63: 0.64261524 | KG63: 1.8544235 | KH63: 2.2377073 | KI63: 1.1520405 | KJ63: 1.354853 | KK63: 2.3015087 | KL63: 2.1335777 | KM63: 2.0336067 | KN63: 4.3394166 | KO63: 0.82184504 | KP63: 1.7479247 | KQ63: 1.8942187 | KR63: 1.9302097 | KS63: 2.8433726 | KT63: -0.55496591 | KU63: 2.7663099 | KV63: 3.3147601 | KW63: 3.6480954 | KX63: 0.14628763 | KY63: -0.46319503 | KZ63: 0.47468926 | LA63: 1.9427533 | LB63: 2.1044919 | LC63: 0.58798482 | LD63: 1.4959106 | LE63: 1.9032487 | LF63: 1.8937824 | LG63: 4.4169393 | LH63: 1.5406609 | LI63: 1.7307819 | LJ63: 1.1663731 | LK63: 2.8710675 | LL63: 3.1926875 | LM63: 2.6379382 | LN63: -0.45968503 | LO63: 1.8485537 | LP63: 1.7338018 | LQ63: 1.1886966 | LR63: 3.0000963 | LS63: 2.958326 | LT63: 0.30171651 | LU63: 4.8065661 | LV63: 0.53612824 | LW63: 1.247101 | LX63: 1.5011541 | LY63: 4.0646762 | LZ63: 1.9686677 | MA63: 1.133299 | MB63: 0.90167792 | MC63: 2.9666198 | MD63: 0.0065905265 | ME63: 1.5150668 | MF63: 3.2508038 | MG63: 1.993532 | MH63: 0.26037523 | MI63: 3.5382161 | MJ63: 1.8263049 | MK63: 2.2008078 | ML63: 2.4677757 | MM63: 3.5624826 | MN63: 1.6182208 | MO63: 1.6986666 | MP63: 2.0198228 | MQ63: 1.6311592 | MR63: 1.0193397 | MS63: 0.24214034 | MT63: 2.1782542 | MU63: 0.31025479 | MV63: 0.28747101 | MW63: 1.6495858 | MX63: 3.1432958 | MY63: 1.0647465 | MZ63: 1.3939443 | NA63: 5.8063723 | NB63: 4.1188599 | NC63: 1.5197106 | ND63: 0.97870093 | NE63: 4.4195998 | NF63: 1.8661198 | NG63: 2.8511855 | NH63: 0.16287528 | NI63: -0.88707842 | NJ63: 1.7551075 | NK63: 2.7133965 | NL63: 4.1629392 | NM63: 0.61902913 | NN63: 2.4699796 | NO63: 0.099779301 | NP63: 2.8962923 | NQ63: 2.1890555 | NR63: 1.4632826 | NS63: 1.4070088 | NT63: 1.3129276 | NU63: 1.2710788 | NV63: 3.250567 | NW63: 1.6825079 | NX63: 1.6984851 | NY63: 1.9685766 | NZ63: 2.6152791 | OA63: 2.7861484 | OB63: -0.25671322 | OC63: 2.5704662 | OD63: 2.4785121 | OE63: 1.7544421 | OF63: 1.6877721 | OG63: 2.5737346 | OH63: 0.81752156 | OI63: -0.091109757 | OJ63: 0.02002528 | OK63: 2.9251996 | OL63: 3.2677204 | OM63: 1.7286001 | ON63: 1.6040039 | OO63: 1.9685037 | OP63: 1.3165574 | OQ63: 2.259405 | OR63: 3.0568594 | OS63: 0.38584393 | OT63: 0.35506603 | OU63: 1.3371229 | OV63: 0.62759131 | OW63: 2.4261969 | OX63: 0.71771876 | OY63: 4.1796757 | OZ63: 2.6538696 | PA63: -0.8817984 | PB63: 0.6957465 | PC63: 1.4694713 | PD63: 0.14505753 | PE63: 2.7053855 | PF63: 1.4575266 | PG63: 3.1730962 | PH63: 2.6347751 | PI63: 1.6296843 | PJ63: 1.7673757 | PK63: 1.9484189 | PL63: 1.2192924 | PM63: 0.1982646 | PN63: 1.8818095 | PO63: 1.1914644 | PP63: 3.8441241 | PQ63: 2.1050617 | PR63: 0.75574035 | PS63: 3.2015698 | PT63: 2.5775408 | PU63: 1.0460434 | PV63: 1.7760331 | PW63: 2.38403 | PX63: 2.3604362 | PY63: 1.2948382 | PZ63: 2.2357139 | QA63: 0.90742486 | QB63: -0.060300957 | QC63: 2.2073004 | QD63: 2.9340177 | QE63: 1.9967024 | QF63: 2.8536858 | QG63: 2.0997957 | QH63: 3.7889872 | QI63: 2.3704195 | QJ63: 1.8062723 | QK63: 1.9268637 | QL63: 2.1042913 | QM63: 4.1120295 | QN63: 3.1182121 | QO63: 0.68547444 | QP63: 0.97481635 | QQ63: 1.7848997 | QR63: 0.75832367 | QS63: -0.30770661 | QT63: 2.5952712 | QU63: 2.1428992 | QV63: 3.452694 | QW63: 2.5043187 | QX63: 2.2619735 | QY63: 1.7953421 | QZ63: 2.3389281 | RA63: 1.1394239 | RB63: 2.9539141 | RC63: 1.0816931 | RD63: 2.0932199 | RE63: 0.3903489 | RF63: 2.5222854 | RG63: 2.9553312 | RH63: 1.8461011 | RI63: 0.6390171 | RJ63: 2.627066 | RK63: 3.3056459 | RL63: -0.90873095 | RM63: 0.085496673 | RN63: 1.5545432 | RO63: 2.6548551 | RP63: 1.8685125 | RQ63: 1.9564498 | RR63: 5.020864 | RS63: 1.7931383 | RT63: 1.5192503 | RU63: 2.1074669 | RV63: 3.2149577 | RW63: 2.2095139 | RX63: 1.913445 | RY63: 2.605824 | RZ63: 3.4572497 | SA63: 1.3579368 | SB63: 0.7407659 | SC63: 0.53643698 | SD63: 1.8209776 | SE63: 0.070614505 | SF63: 2.7827755 | SG63: 1.7049296 | SH63: 1.6031695 | SI63: 4.3031677 | SJ63: 0.37103187 | SK63: -1.4630821 | SL63: 2.2640188 | SM63: 1.5339985 | SN63: 1.8822947 | SO63: 2.3933367 | SP63: -0.53321357 | SQ63: 1.2264258 | SR63: 1.0686715 | SS63: 1.448337 | ST63: 2.1042089 | SU63: -0.11530683 | SV63: 2.7155516 | SW63: 1.1272387 | SX63: 2.5543871 | SY63: 3.6248541 | SZ63: 3.4993515 | TA63: 1.069333 | TB63: -0.97840895 | TC63: 0.51830993 | TD63: 1.6161569 | TE63: 3.8783363 | TF63: 3.6826229 | TG63: -0.18178071 | TH63: 3.285002 | TI63: 1.7538698 | TJ63: 2.4666314 | TK63: 0.13415302 | TL63: 0.20113427 | TM63: 2.0940628 | TN63: 1.9331669 | TO63: -0.92706512 | TP63: 0.68723593 | TQ63: 0.81789361 | TR63: 1.6561948 | TS63: 1.5564569 | TT63: 0.79655611 | TU63: 1.5700654 | TV63: 0.46835866 | TW63: 1.6962428 | TX63: 0.99050593 | TY63: 2.0508376 | TZ63: 1.5852445 | UA63: 1.2324419 | UB63: 2.7406423 | UC63: 1.6120979 | UD63: 3.0394405 | UE63: 2.6789959 | UF63: 1.9024856 | UG63: 2.3644168 | UH63: 1.5498219 | UI63: 1.6538546 | UJ63: 1.0813388 | UK63: 0.28496083 | UL63: -0.73240592 | UM63: 2.6259822 | UN63: 2.5464796 | UO63: 3.9167015 | UP63: 1.5641268 | UQ63: 1.3985911 | UR63: 1.335159 | US63: -0.45094555 | UT63: 2.3923459 | UU63: 3.1555336 | UV63: 0.3739156 | UW63: 1.3196779 | UX63: 0.094611761 | UY63: -0.66235129 | UZ63: 2.0815516 | VA63: -0.14989577 | VB63: 2.1073871 | VC63: 1.5764457 | VD63: 2.2165242 | VE63: 3.1512784 | VF63: 0.40658344 | VG63: 0.77892637 | VH63: 0.80474114 | VI63: -0.30986 | VJ63: 1.2031832 | VK63: 5.3985094 | VL63: 0.58137589 | VM63: 1.901751 | VN63: -0.65615674 | VO63: 1.3919548 | VP63: 2.4356188 | VQ63: 2.9274763 | VR63: -1.6584934 | VS63: 2.1875641 | VT63: 1.1821839 | VU63: 2.9819557 | VV63: 0.26093493 | VW63: 0.70798683 | VX63: 2.2459341 | VY63: 3.5795392 | VZ63: 1.58294 | WA63: 2.7027779 | WB63: 1.0818861 | WC63: 3.1734224 | WD63: -0.23179257 | WE63: 1.6017803 | WF63: 3.0653659 | WG63: 1.651249 | WH63: 1.1813389 | WI63: -0.45386399 | WJ63: 1.3071228 | WK63: 2.5350599 | WL63: 1.821855 | WM63: 3.1856772 | WN63: 2.0424466 | WO63: 1.8320865 | WP63: 2.0998151 | WQ63: 3.1871787 | WR63: 2.4140117 | WS63: 1.7264338 | WT63: -0.012114419 | WU63: 1.4304775 | WV63: 3.9580037 | WW63: 2.6412298 | WX63: 2.5200028 | WY63: 0.95733089 | WZ63: 2.1802942 | XA63: -0.11194746 | XB63: 0.94934721 | XC63: 3.0422672 | XD63: 2.5883221 | XE63: 1.074335 | XF63: 1.502146 | XG63: 0.43988331 | XH63: 2.9546807 | XI63: 0.26983861 | XJ63: 2.1442916 | XK63: 1.3315949 | XL63: 3.7096188 | XM63: -0.2682414 | XN63: 1.0761523 | XO63: 1.6916565 | XP63: 3.0709537 | XQ63: -0.21515751 | XR63: 1.490481 | XS63: 3.1089562 | XT63: 1.3693674 | XU63: -0.40608371 | XV63: 2.2204676 | XW63: 3.6368889 | XX63: 2.2698253 | XY63: 3.4048619 | XZ63: 2.849066 | YA63: 2.1934513 | YB63: 3.6862633 | YC63: 1.6038347 | YD63: 0.41683469 | YE63: 2.7814367 | YF63: 0.93512494 | YG63: 0.43114957 | YH63: -1.4680674 | YI63: 3.0373191 | YJ63: -0.43342718 | YK63: 2.8383525 | YL63: 1.418109 | YM63: 1.9882167 | YN63: 2.7577998 | YO63: 2.3583092 | YP63: 1.4526404 | YQ63: 3.398407 | YR63: 2.3426652 | YS63: 1.0860003 | YT63: 2.4423022 | YU63: 0.64214197 | YV63: 1.6617378 | YW63: 2.2591994 | YX63: 0.77937707 | YY63: 0.50620945 | YZ63: 1.4054595 | ZA63: 1.08573 | ZB63: 1.5847227 | ZC63: 2.7720405 | ZD63: 1.730364 | ZE63: 1.6058386 | ZF63: -1.0781427 | ZG63: 3.1793868 | ZH63: 1.3575661 | ZI63: 0.64942475 | ZJ63: 1.3023593 | ZK63: 1.4239408 | ZL63: 1.8168852 | ZM63: 2.300272 | ZN63: 2.4035885 | ZO63: 1.1268523 | ZP63: 1.3641414 | ZQ63: 2.808167 | ZR63: 1.5029865 | ZS63: 1.8353215 | ZT63: -0.73104171 | ZU63: 1.0819386 | ZV63: 2.780585 | ZW63: 1.5352889 | ZX63: 2.6411249 | ZY63: 1.0175305 | ZZ63: 3.2975099 | AAA63: 3.5412477 | AAB63: 2.96768 | AAC63: 1.4484741 | AAD63: 2.4955956 | AAE63: -0.07937871 | AAF63: 1.3993201 | AAG63: 1.1741109 | AAH63: 2.9749532 | AAI63: 1.6285362 | AAJ63: 2.9977196 | AAK63: 2.118168 | AAL63: 0.83949784 | AAM63: 0.70242584 | AAN63: 5.3974417 | AAO63: 1.6553223 | AAP63: 1.211291 | AAQ63: -0.34344359 | AAR63: -1.1046587 | AAS63: 0.27007572 | AAT63: 1.7665683 | AAU63: 2.0222947 | AAV63: 1.5621753 | AAW63: 2.5957032 | AAX63: 3.2403843 | AAY63: 1.2215023 | AAZ63: 0.092459209 | ABA63: 1.0091399 | ABB63: 2.08492 | ABC63: 2.3785539 | ABD63: 1.9963981 | ABE63: 1.8690371 | ABF63: -0.99430473 | ABG63: 1.4086089 | ABH63: 2.6241521 | ABI63: 2.3849093 | ABJ63: 2.1344689 | ABK63: 3.3952251 | ABL63: 3.2744191 | ABM63: 2.0088919 | ABN63: 1.010489 | ABO63: 3.567392 | ABP63: 0.019905641 | ABQ63: 2.8033986 | ABR63: 2.4315164 | ABS63: 3.6855749 | ABT63: 2.4688657 | ABU63: 1.4952078 | ABV63: 0.86171858 | ABW63: 3.0722072 | ABX63: 0.5464808 | ABY63: 1.8051396 | ABZ63: 0.8369804 | ACA63: 1.634101 | ACB63: 1.6750476 | ACC63: 1.1471032 | ACD63: 0.36631605 | ACE63: 1.7253868 | ACF63: 0.24547533 | ACG63: 0.82256865 | ACH63: 0.35606258 | ACI63: 1.6211711 | ACJ63: 1.8670048 | ACK63: 0.85685162 | ACL63: 2.1141451 | ACM63: 1.1038781 | ACN63: 1.5865562 | ACO63: 1.1063433 | ACP63: 1.862523 | ACQ63: 0.95875113 | ACR63: 4.9249411 | ACS63: 3.5604694 | ACT63: 1.8875668 | ACU63: 3.8823699 | ACV63: -0.55529503 | ACW63: 1.9714986 | ACX63: 3.0789591 | ACY63: 2.6425966 | ACZ63: 0.17272772 | ADA63: 2.2053012 | ADB63: 2.3877159 | ADC63: -0.06758311 | ADD63: 1.7925042 | ADE63: 1.0040475 | ADF63: 1.8900759 | ADG63: 2.2750579 | ADH63: 1.5670402 | ADI63: 3.0579549 | ADJ63: 2.7465889 | ADK63: 3.2754268 | ADL63: 2.1295558 | ADM63: 0.53895116 | ADN63: 1.1989391 | ADO63: 1.078232 | ADP63: 2.7410593 | ADQ63: 2.7417874 | ADR63: 0.93041407 | ADS63: 3.2642224 | ADT63: 2.1927048 | ADU63: -1.3615098 | ADV63: 1.5731721 | ADW63: -0.22756833 | ADX63: 3.5658492 | ADY63: 0.57603515 | ADZ63: 1.2422807 | AEA63: 1.2418526 | AEB63: 0.77701654 | AEC63: 3.8426146 | AED63: 0.86751061 | AEE63: 1.1814708 | AEF63: 3.3965575 | AEG63: 3.8750875 | AEH63: 2.8539564 | AEI63: 4.5610236 | AEJ63: 3.80243 | AEK63: 0.95081478 | AEL63: -0.67982485 | AEM63: 4.5807049 | AEN63: 2.9038132 | AEO63: 2.8525317 | AEP63: 1.6707848 | AEQ63: 1.5232553 | AER63: 0.67130521 | AES63: 0.54477103 | AET63: 2.9982045 | AEU63: 0.61984957 | AEV63: 2.6647133 | AEW63: 2.5116097 | AEX63: 2.154363 | AEY63: 0.21139777 | AEZ63: 1.4884816 | AFA63: 2.3058343 | AFB63: 1.3295248 | AFC63: -1.2913819 | AFD63: -0.69162323 | AFE63: 1.2663927 | AFF63: 2.1375777 | AFG63: 1.4355485 | AFH63: 1.886251 | AFI63: 2.9293791 | AFJ63: 0.10310028 | AFK63: 2.8004607 | AFL63: 0.5243729 | AFM63: 0.54709532 | AFN63: 0.98781524 | AFO63: 1.4076139 | AFP63: 3.2016092 | AFQ63: 1.6105241 | AFR63: 0.64772704 | AFS63: 0.62958783 | AFT63: 0.63385778 | AFU63: 2.9931276 | AFV63: 0.83373983 | AFW63: 1.0713871 | AFX63: 1.7488894 | AFY63: 1.3774997 | AFZ63: 1.4746276 | AGA63: 3.4922474 | AGB63: -0.31925874 | AGC63: 3.5899726 | AGD63: 1.6240738 | AGE63: 2.0285139 | AGF63: 0.70283086 | AGG63: 0.74003319 | AGH63: 2.9618281 | AGI63: 3.0272008 | AGJ63: 1.1031683 | AGK63: 2.6372067 | AGL63: 1.8945111 | AGM63: 3.7555384 | AGN63: 0.98279329 | AGO63: 1.7898129 | AGP63: 1.7348893 | AGQ63: 1.3619387 | AGR63: 1.3499859 | AGS63: 1.0948819 | AGT63: 1.6042161 | AGU63: 2.6431523 | AGV63: 0.68584352 | AGW63: 1.2646065 | AGX63: 1.6784147 | AGY63: 2.521644 | AGZ63: 1.3722653 | AHA63: 1.5715938 | AHB63: 0.90092318 | AHC63: 4.5384563 | AHD63: 0.19279314 | AHE63: 3.6339572 | AHF63: 2.2186457 | AHG63: 0.99523452 | AHH63: 1.1359487 | AHI63: -0.092075787 | AHJ63: 3.5656416 | AHK63: 0.705618 | AHL63: -0.94282725 | AHM63: 0.71129469 | AHN63: 0.41430271 | AHO63: 0.65984942 | AHP63: 1.3004287 | AHQ63: 0.011423673 | AHR63: 1.6602077 | AHS63: 2.8128143 | AHT63: 2.2613682 | AHU63: 0.69052623 | AHV63: 1.7152525 | AHW63: -1.1431576 | AHX63: 2.383158 | AHY63: 1.2631363 | AHZ63: -1.7310874 | AIA63: -0.60207846 | AIB63: 2.4603709 | AIC63: 0.17651119 | AID63: 1.8579434 | AIE63: 0.86232929 | AIF63: 1.2128873 | AIG63: 1.2080319 | AIH63: 0.56492299 | AII63: 3.4388282 | AIJ63: 2.5110098 | AIK63: 2.5217017 | AIL63: 0.41345722 | AIM63: 1.6456324 | AIN63: 1.9532603 | AIO63: 3.6416752 | AIP63: 2.0922461 | AIQ63: 2.3054572 | AIR63: 0.89333103 | AIS63: 0.95618545 | AIT63: 3.4430194 | AIU63: 1.0960951 | AIV63: 2.7914404 | AIW63: 1.336154 | AIX63: 1.5895105 | AIY63: 1.6065257 | AIZ63: -0.126471 | AJA63: 0.067138481 | AJB63: 1.058621 | AJC63: 4.3774858 | AJD63: 2.6654279 | AJE63: 1.9113235 | AJF63: -0.58608444 | AJG63: 4.3857877 | AJH63: 1.1339746 | AJI63: 3.0970125 | AJJ63: 2.8182246 | AJK63: 0.23935581 | AJL63: 1.5708787 | AJM63: 3.3133111 | AJN63: 1.3590041 | AJO63: 1.1905966 | AJP63: 1.5186103 | AJQ63: 2.9758131 | AJR63: 0.53239194 | AJS63: 1.5480135 | AJT63: 1.2900727 | AJU63: 1.8867309 | AJV63: 1.5211838 | AJW63: -0.05854373 | AJX63: -0.034533177 | AJY63: 0.5587099 | AJZ63: 0.6678876 | AKA63: 1.3495628 | AKB63: 2.8999526 | AKC63: 2.8656381 | AKD63: 1.5530574 | AKE63: 3.945138 | AKF63: 2.3512924 | AKG63: 3.6070733 | AKH63: 1.4453297 | AKI63: 2.4769766 | AKJ63: 1.020289 | AKK63: 2.2192481 | AKL63: 3.2639064 | AKM63: 0.74061255 | AKN63: 0.37057643 | AKO63: 3.0576767 | AKP63: 1.316971 | AKQ63: 1.188065 | AKR63: 2.1398414 | AKS63: 1.9776613 | AKT63: 0.075894841 | AKU63: 2.0834814 | AKV63: 1.8540402 | AKW63: 1.484287 | AKX63: 2.9528397 | AKY63: -0.085181386 | AKZ63: 1.1782107 | ALA63: 2.3616278 | ALB63: 2.0526311 | ALC63: 1.349289 | ALD63: 2.9239785 | ALE63: 2.6001349 | ALF63: 1.01338 | ALG63: 2.81666 | ALH63: -0.041809205 | ALI63: 1.5557319 | ALJ63: 2.7268419 | ALK63: -0.73881223 | ALL63: 2.568411 | ALM63: -0.22222771
